[DataFileDownloadDirectory 2023-05-24 11:13:16] ERROR: encountered an exception when gathering initial "ucsb_indentation_data" topic offsets for consumer group ID "create_new". The error will be logged below and re-raised.
Traceback (most recent call last):
  File "/home/openmsi/.local/lib/python3.9/site-packages/openmsistream/kafka_wrapper/consumer_group.py", line 170, in __get_group_starting_offsets
    tp_offsets = kafka.KafkaAdminClient(
  File "/home/openmsi/.local/lib/python3.9/site-packages/kafka/admin/client.py", line 1265, in list_consumer_group_offsets
    group_coordinator_id = self._find_coordinator_ids([group_id])[group_id]
  File "/home/openmsi/.local/lib/python3.9/site-packages/kafka/admin/client.py", line 348, in _find_coordinator_ids
    groups_coordinators = {
  File "/home/openmsi/.local/lib/python3.9/site-packages/kafka/admin/client.py", line 349, in <dictcomp>
    group_id: self._find_coordinator_id_process_response(future.value)
  File "/home/openmsi/.local/lib/python3.9/site-packages/kafka/admin/client.py", line 322, in _find_coordinator_id_process_response
    raise error_type(
kafka.errors.GroupAuthorizationFailedError: [Error 30] GroupAuthorizationFailedError: FindCoordinatorRequest failed with response 'GroupCoordinatorResponse_v0(error_code=30, coordinator_id=-1, host='', port=-1)'.
